<?xml version="1.0" encoding="utf-8"?>
<!-- This URDF was automatically created by SolidWorks to URDF Exporter! Originally created by Stephen Brawner (brawner@gmail.com) 
     Commit Version: 1.6.0-1-g15f4949  Build Version: 1.6.7594.29634
     For more information, please see http://wiki.ros.org/sw_urdf_exporter -->
<robot
  name="model4_new">

  <link 
    name= "dummy_link">
  </link>  

  <link
    name="base_link">
    <inertial>
      <origin
        xyz="0.10394 -0.0029832 -8.5535E-18"
        rpy="0 0 0" />
      <mass
        value="11.944" />
      <inertia
        ixx="0.17567"
        ixy="0.023351"
        ixz="7.4916E-17"
        iyy="0.86961"
        iyz="4.3047E-18"
        izz="0.7189" />
    </inertial>
    <visual>
      <origin
        xyz="0 0 0"
        rpy="0 0 0" />
      <geometry>
        <mesh
          filename="package://model4_new/meshes/base_link.STL" />
      </geometry>
      <material
        name="">
        <color
          rgba="0.79216 0.81961 0.93333 1" />
      </material>
    </visual>
    <collision>
      <origin
        xyz="0 0 0"
        rpy="0 0 0" />
      <geometry>
        <mesh
          filename="package://model4_new/meshes/base_link.STL" />
      </geometry>
    </collision>
  </link>

  <joint
    name= "dummy_joint"
    type="fixed">
    <parent 
    link="dummy_link"/>
    <child
    link="base_link"/>
  </joint> 

  <link
    name="rear_axle">
    <inertial>
      <origin
        xyz="-2.77555756156289E-17 -6.93889390390723E-18 -3.29063169625062E-17"
        rpy="0 0 0" />
      <mass
        value="1.44148143653656" />
      <inertia
        ixx="0.0466598415056552"
        ixy="-5.92249757537018E-37"
        ixz="-4.01606554724839E-19"
        iyy="0.0466598415056552"
        iyz="-4.07187056796288E-34"
        izz="0.000863558580481933" />
    </inertial>
    <visual>
      <origin
        xyz="0 0 0"
        rpy="0 0 0" />
      <geometry>
        <mesh
          filename="package://model4_new/meshes/rear_axle.STL" />
      </geometry>
      <material
        name="">
        <color
          rgba="0.792156862745098 0.819607843137255 0.933333333333333 1" />
      </material>
    </visual>
    <collision>
      <origin
        xyz="0 0 0"
        rpy="0 0 0" />
      <geometry>
        <mesh
          filename="package://model4_new/meshes/rear_axle.STL" />
      </geometry>
    </collision>
  </link>
  <joint
    name="base_rear_axle"
    type="revolute">
    <origin
      xyz="0.2286 0 -0.0508"
      rpy="1.5708 0 0" />
    <parent
      link="base_link" />
    <child
      link="rear_axle" />
    <axis
      xyz="0 0 1" />
    <limit
      lower="0"
      upper="0"
      effort="0"
      velocity="0" />
  </joint>
  <link
    name="wheel3">
    <inertial>
      <origin
        xyz="8.64218918650295E-10 5.55111512312578E-17 0.0367997448515429"
        rpy="0 0 0" />
      <mass
        value="2.18102510469599" />
      <inertia
        ixx="0.0080679819070274"
        ixy="-6.34628215864103E-11"
        ixz="-1.00286817770486E-10"
        iyy="0.00806798198466086"
        iyz="2.67522980992825E-18"
        izz="0.0141652900371572" />
    </inertial>
    <visual>
      <origin
        xyz="0 0 0"
        rpy="0 0 0" />
      <geometry>
        <mesh
          filename="package://model4_new/meshes/wheel3.STL" />
      </geometry>
      <material
        name="">
        <color
          rgba="0.792156862745098 0.819607843137255 0.933333333333333 1" />
      </material>
    </visual>
    <collision>
      <origin
        xyz="0 0 0"
        rpy="0 0 0" />
      <geometry>
        <mesh
          filename="package://model4_new/meshes/wheel3.STL" />
      </geometry>
    </collision>
  </link>
  <joint
    name="rear_axle_wheel3"
    type="continuous">
    <origin
      xyz="0 0 -0.1905"
      rpy="3.1416 0 -2.7485" />
    <parent
      link="rear_axle" />
    <child
      link="wheel3" />
    <axis
      xyz="0 0 1" />
  </joint>
  <link
    name="wheel4">
    <inertial>
      <origin
        xyz="8.64218807627992E-10 -1.38777878078145E-17 0.036799744851543"
        rpy="0 0 0" />
      <mass
        value="2.181025104696" />
      <inertia
        ixx="0.0080679819070274"
        ixy="-6.34628213676971E-11"
        ixz="-1.00286818271925E-10"
        iyy="0.00806798198466086"
        iyz="1.82270810257325E-18"
        izz="0.0141652900371572" />
    </inertial>
    <visual>
      <origin
        xyz="0 0 0"
        rpy="0 0 0" />
      <geometry>
        <mesh
          filename="package://model4_new/meshes/wheel4.STL" />
      </geometry>
      <material
        name="">
        <color
          rgba="0.792156862745098 0.819607843137255 0.933333333333333 1" />
      </material>
    </visual>
    <collision>
      <origin
        xyz="0 0 0"
        rpy="0 0 0" />
      <geometry>
        <mesh
          filename="package://model4_new/meshes/wheel4.STL" />
      </geometry>
    </collision>
  </link>
  <joint
    name="rear_axle_wheel4"
    type="continuous">
    <origin
      xyz="0 0 0.1905"
      rpy="0 0 0" />
    <parent
      link="rear_axle" />
    <child
      link="wheel4" />
    <axis
      xyz="0 0 1" />
  </joint>
  <link
    name="front_axle">
    <inertial>
      <origin
        xyz="-3.90341147182838E-08 -0.0407988330271113 -1.04380367389723E-17"
        rpy="0 0 0" />
      <mass
        value="1.73241164957737" />
      <inertia
        ixx="0.0477807013752999"
        ixy="3.22917081844805E-11"
        ixz="1.64154002677884E-11"
        iyy="0.0469539126224443"
        iyz="5.23906982083041E-19"
        izz="0.00198629842988332" />
    </inertial>
    <visual>
      <origin
        xyz="0 0 0"
        rpy="0 0 0" />
      <geometry>
        <mesh
          filename="package://model4_new/meshes/front_axle.STL" />
      </geometry>
      <material
        name="">
        <color
          rgba="0.792156862745098 0.819607843137255 0.933333333333333 1" />
      </material>
    </visual>
    <collision>
      <origin
        xyz="0 0 0"
        rpy="0 0 0" />
      <geometry>
        <mesh
          filename="package://model4_new/meshes/front_axle.STL" />
      </geometry>
    </collision>
  </link>
  <joint
    name="base_front_axle"
    type="revolute">
    <origin
      xyz="-0.2794 0 0"
      rpy="1.5708 0 0" />
    <parent
      link="base_link" />
    <child
      link="front_axle" />
    <axis
      xyz="0 1 0" />
    <limit
      lower="-0.4"
      upper="0.4"
      effort="50"
      velocity="100" />
  </joint>
  <link
    name="wheel1">
    <inertial>
      <origin
        xyz="8.64262772459767E-10 -4.04051792024518E-14 0.0367997448515424"
        rpy="0 0 0" />
      <mass
        value="2.18102510469405" />
      <inertia
        ixx="0.0080679819070233"
        ixy="-6.34669398199422E-11"
        ixz="-1.00286870793171E-10"
        iyy="0.00806798198465566"
        iyz="5.07288407443803E-17"
        izz="0.014165290037149" />
    </inertial>
    <visual>
      <origin
        xyz="0 0 0"
        rpy="0 0 0" />
      <geometry>
        <mesh
          filename="package://model4_new/meshes/wheel1.STL" />
      </geometry>
      <material
        name="">
        <color
          rgba="0.792156862745098 0.819607843137255 0.933333333333333 1" />
      </material>
    </visual>
    <collision>
      <origin
        xyz="0 0 0"
        rpy="0 0 0" />
      <geometry>
        <mesh
          filename="package://model4_new/meshes/wheel1.STL" />
      </geometry>
    </collision>
  </link>
  <joint
    name="front_axle_wheel1"
    type="continuous">
    <origin
      xyz="0 -0.0508 -0.1905"
      rpy="3.1416 0 -2.7485" />
    <parent
      link="front_axle" />
    <child
      link="wheel1" />
    <axis
      xyz="0 0 1" />
  </joint>
  <link
    name="wheel2">
    <inertial>
      <origin
        xyz="8.64218807627992E-10 0 0.0367997448515429"
        rpy="0 0 0" />
      <mass
        value="2.18102510469599" />
      <inertia
        ixx="0.0080679819070274"
        ixy="-6.34628210829401E-11"
        ixz="-1.0028681789848E-10"
        iyy="0.00806798198466086"
        iyz="2.30316122595499E-18"
        izz="0.0141652900371572" />
    </inertial>
    <visual>
      <origin
        xyz="0 0 0"
        rpy="0 0 0" />
      <geometry>
        <mesh
          filename="package://model4_new/meshes/wheel2.STL" />
      </geometry>
      <material
        name="">
        <color
          rgba="0.792156862745098 0.819607843137255 0.933333333333333 1" />
      </material>
    </visual>
    <collision>
      <origin
        xyz="0 0 0"
        rpy="0 0 0" />
      <geometry>
        <mesh
          filename="package://model4_new/meshes/wheel2.STL" />
      </geometry>
    </collision>
  </link>
  <joint
    name="front_axle_wheel2"
    type="continuous">
    <origin
      xyz="0 -0.0508 0.1905"
      rpy="0 0 0" />
    <parent
      link="front_axle" />
    <child
      link="wheel2" />
    <axis
      xyz="0 0 1" />
  </joint>

<transmission name="streering_trans1">
  <type>SimpleTransmission</type>
  <joint name="base_front_axle">
    <hardwareInterface>hardware_interface/PositionJointInterface</hardwareInterface>
  </joint>
  <actuator name="steer_motor1">
    <mechanicalReduction>50</mechanicalReduction>
    <hardwareInterface>hardware_interface/PositionJointInterface</hardwareInterface>
  </actuator>
</transmission>
 
<transmission name="drive_trans1">
  <type>SimpleTransmission</type>
  <joint name="front_axle_wheel1">
    <hardwareInterface>hardware_interface/VelocityJointInterface</hardwareInterface>
  </joint>
  <actuator name="drive_motor1">
    <mechanicalReduction>50</mechanicalReduction>
    <hardwareInterface>hardware_interface/VelocityJointInterface</hardwareInterface>
  </actuator>
</transmission>
  
<transmission name="drive_trans2">
  <type>SimpleTransmission</type>
  <joint name="front_axle_wheel2">
    <hardwareInterface>hardware_interface/VelocityJointInterface</hardwareInterface>
  </joint>
  <actuator name="drive_motor2">
    <mechanicalReduction>50</mechanicalReduction>
    <hardwareInterface>hardware_interface/VelocityJointInterface</hardwareInterface>
  </actuator>
</transmission>
  
<transmission name="drive_trans3">
  <type>SimpleTransmission</type>
  <joint name="rear_axle_wheel3">
    <hardwareInterface>hardware_interface/VelocityJointInterface</hardwareInterface>
  </joint>
  <actuator name="drive_motor3">
    <mechanicalReduction>50</mechanicalReduction>
    <hardwareInterface>hardware_interface/VelocityJointInterface</hardwareInterface>
  </actuator>
</transmission>
  
<transmission name="drive_trans4">
  <type>SimpleTransmission</type>
  <joint name="rear_axle_wheel4">
    <hardwareInterface>hardware_interface/VelocityJointInterface</hardwareInterface>
  </joint>
  <actuator name="drive_motor4">
    <mechanicalReduction>50</mechanicalReduction>
    <hardwareInterface>hardware_interface/VelocityJointInterface</hardwareInterface>
  </actuator>
</transmission>

</robot>
